<?xml version="1.0"?>
<robot xmlns:xacro="http://www.ros.org/wiki/xacro">

    <xacro:include filename="inertial_macros.xacro"/>

    <material name="white">
        <color rgba="1 1 1 1" />
    </material>

    <material name="orange">
        <color rgba="1 0.3 0.1 1"/>
    </material>

    <material name="blue">
        <color rgba="0.2 0.2 1 1"/>
    </material>

    <material name="black">
        <color rgba="0 0 0 1"/>
    </material>

    <material name="red">
        <color rgba="1 0 0 1"/>
    </material>

    <!-- URDF CREATION NOTES: According to urdf creation standards for diff drive robots 
     we want the base_link to sit in between the wheels. We basically design our entire robot around the base_link because 
     I reckon it helps us with creating the controller and all the kinematics jazz-->

    <!-- BASE LINK -->

    <link name = "base_link">

    </link>

    <!-- CHASSIS LINK -->

    <joint name = "chassis_joint" type = "fixed">
        <parent link = "base_link"/>
        <child link = "chassis_link"/>
        <origin xyz = "-0.1 0 0"/> <!-- We want the chassis link to sit at the edge of the chassis (100 cm behind the wheels)-->
    </joint> 

    <!-- By default the visual of the link centers around the location of the joint
            so we offset its position in the origin tag to get it where we want it -->

    <link name = "chassis_link">
        <visual>
            <origin xyz = "0.15 0 0.075"/> 
            <geometry>
                <box size = "0.3 0.3 0.15"/>
            </geometry>
            <material name = "white"/>
        </visual>

        <collision>
            <origin xyz = "0.15 0 0.075"/> 
            <geometry>
                <box size = "0.3 0.3 0.15"/>
            </geometry>
        </collision>

        <xacro:inertial_box mass = "0.5" x = "0.3" y = "0.3" z = "0.15">
            <origin xyz = "0.15 0 0.075" rpy = "0 0 0"/> 
        </xacro:inertial_box>
    </link>

    <!-- LEFT WHEEL LINK -->


    <!--By default cyliders are oriented along the x axis so we have to rotate them in the urdf so that they look right-->
    <!--Z axis of the wheels should also be pointing away from the robot-->

    <joint name = "left_wheel_joint" type = "continuous">
        <parent link = "base_link"/>
        <child link = "left_wheel_link"/>
        <origin xyz = "0 0.175 0" rpy = "-${pi/2} 0 0"/>
        <axis xyz = "0 0 1"/>
        <limit effort="0.05" velocity="10.0"/> <!-- Tag to limit torque and velocity within gazebo sim to make movement feel smooth-->
    </joint> 
    
    <link name = "left_wheel_link">
        <visual>
            <geometry>
                <cylinder radius = "0.05" length="0.04"/>
            </geometry>
            <material name = "blue"/>
        </visual>

        <collision>
            <geometry>
                <sphere radius = "0.05"/>
            </geometry>
        </collision>

        <xacro:inertial_cylinder mass = "0.1" length = "0.04" radius = "0.05">
            <origin xyz = "0 0 0" rpy = "0 0 0"/> 
        </xacro:inertial_cylinder>
    </link>


    <!-- RIGHT WHEEL LINK -->


    <joint name = "right_wheel_joint" type = "continuous">
        <parent link = "base_link"/>
        <child link = "right_wheel_link"/>
        <origin xyz = "0 -0.175 0" rpy = "${pi/2} 0 0"/>
        <axis xyz = "0 0 -1"/>
        <limit effort="0.05" velocity="10.0"/> <!-- Tag to limit torque and velocity within gazebo sim to make movement feel smooth-->
    </joint> 
    
    <link name = "right_wheel_link">
        <visual>
            <geometry>
                <cylinder radius = "0.05" length="0.04"/>
            </geometry>
            <material name = "blue"/>
        </visual>

        <collision>
            <geometry>
                <sphere radius = "0.05"/>
            </geometry>
        </collision>

        <xacro:inertial_cylinder mass = "0.1" length = "0.04" radius = "0.05">
            <origin xyz = "0 0 0" rpy = "0 0 0"/> 
        </xacro:inertial_cylinder>
    </link>

    <!-- CASTER WHEEL LINK -->

    <joint name = "caster_wheel_joint" type = "fixed">
        <parent link = "chassis_link" />
        <child link = "caster_wheel_link"/>
        <origin xyz = "0.24 0 0"/>
    </joint>

    <link name ="caster_wheel_link">
        <visual>
            <geometry>
                <sphere radius = "0.05"/>
            </geometry>
            <material name = "black"/>
        </visual>

        <collision>
            <geometry>
                <sphere radius = "0.05"/>
            </geometry>
        </collision>

        <xacro:inertial_sphere mass = "0.1" radius = "0.05">
            <origin xyz = "0 0 0" rpy = "0 0 0"/> 
        </xacro:inertial_sphere>
    </link>


    <!-- Gazebo tag to make the caster wheel frictionless-->
    <gazebo reference="caster_wheel_link">
        <mu1 value="0.0"/>
        <mu2 value="0.0"/>
    </gazebo>

</robot>